#VRML_SIM R2025a utf8

EXTERNPROTO "https://raw.githubusercontent.com/cyberbotics/webots/R2025a/projects/objects/backgrounds/protos/TexturedBackground.proto"
EXTERNPROTO "https://raw.githubusercontent.com/cyberbotics/webots/R2025a/projects/objects/backgrounds/protos/TexturedBackgroundLight.proto"
EXTERNPROTO "https://raw.githubusercontent.com/cyberbotics/webots/R2025a/projects/objects/floors/protos/RectangleArena.proto"
EXTERNPROTO "https://raw.githubusercontent.com/cyberbotics/webots/R2025a/projects/objects/factory/containers/protos/WoodenBox.proto"

WorldInfo {
}
Viewpoint {
  orientation -0.5773117806178613 0.571567353402514 0.5831139412535771 2.094457733901448
  position 0.005850465553401241 0.06570891984892258 2.725971036315837
}
TexturedBackground {
}
TexturedBackgroundLight {
}
RectangleArena {
  translation 0 0.15 0.01
  floorAppearance NULL
}
Solid {
  translation 0.290002 0.48 0.01
  rotation 0 0 1 1.57079
  children [
    Shape {
      appearance PBRAppearance {
        baseColor 0 0 0
        roughness 1
        metalness 0
      }
      geometry Box {
        size 0.01 0.09 0.0001
      }
    }
  ]
  name "solid(35)"
}
Solid {
  translation 0.210002 0.48 0.01
  rotation 0 0 1 1.57079
  children [
    Shape {
      appearance PBRAppearance {
        baseColor 0 0 0
        roughness 1
        metalness 0
      }
      geometry Box {
        size 0.01 0.09 0.0001
      }
    }
  ]
  name "solid(34)"
}
Solid {
  translation 0.210002 0.38 0.01
  rotation 0 0 1 1.57079
  children [
    Shape {
      appearance PBRAppearance {
        baseColor 0 0 0
        metalness 0
      }
      geometry Box {
        size 0.01 0.09 0.0001
      }
    }
  ]
  name "solid(16)"
}
Solid {
  translation 0.300002 0.48 0.01
  rotation 0 0 1 1.57079
  children [
    Shape {
      appearance PBRAppearance {
        baseColor 0 0 0
        roughness 1
        metalness 0
      }
      geometry Box {
        size 0.01 0.09 0.0001
      }
    }
  ]
  name "solid(36)"
}
Solid {
  translation 0.300002 0.38 0.01
  rotation 0 0 1 1.57079
  children [
    Shape {
      appearance PBRAppearance {
        baseColor 0 0 0
        metalness 0
      }
      geometry Box {
        size 0.01 0.09 0.0001
      }
    }
  ]
  name "solid(15)"
}
Solid {
  translation 0.090002 0.38 0.01
  rotation 0 0 1 1.57079
  children [
    Shape {
      appearance PBRAppearance {
        baseColor 0 0 0
        metalness 0
      }
      geometry Box {
        size 0.01 0.09 0.0001
      }
    }
  ]
  name "solid(11)"
}
WoodenBox {
  translation -0.139994 0.480002 0.0596076
  rotation -4.0528298456863077e-10 2.7972396232114287e-11 -1 3.0403922895366876e-05
  name "wooden box(1)"
  size 0.1 0.1 0.1
  mass 1
}
WoodenBox {
  translation -0.31000007026018617 0.2300066438834753 0.05960760000000006
  rotation -4.0528298456863077e-10 2.7972396232114287e-11 -1 3.0403922895366876e-05
  size 0.1 0.1 0.1
  mass 1
}
Robot {
  translation 0.338859 -0.276093 0.0280602
  rotation 0.0012112203199326893 -6.829061803833764e-05 0.9999992641405933 3.05972
  children [
    Lidar {
      translation 4.07848e-08 -0.04 0
      rotation 0 0 1 -1.5707953071795862
      fieldOfView 4.08
      numberOfLayers 1
      maxRange 0.12
    }
    DistanceSensor {
      translation 0.02 -0.0370711 -0.00707099
      rotation 0.35740699927911007 0.35740699927911007 -0.8628559982596194 1.71777
      name "ps4"
      type "infra-red"
    }
    DistanceSensor {
      translation 0.01 -0.0370711 -0.007071
      rotation 0.35740699927911007 0.35740699927911007 -0.8628559982596194 1.71777
      name "ps3"
      type "infra-red"
    }
    DistanceSensor {
      translation -1.35048e-14 -0.0370711 -0.00707101
      rotation 0.35740699927911007 0.35740699927911007 -0.8628559982596194 1.71777
      name "ps2"
      type "infra-red"
    }
    DistanceSensor {
      translation -0.01 -0.0370711 -0.00707102
      rotation 0.35740699927911007 0.35740699927911007 -0.8628559982596194 1.71777
      name "ps1"
      type "infra-red"
    }
    DistanceSensor {
      translation -0.02 -0.0370711 -0.00707103
      rotation 0.35740699927911007 0.35740699927911007 -0.8628559982596194 1.71777
      name "ps0"
      type "infra-red"
    }
    Camera {
      translation 0 -0.04 0.007
      rotation 0 0 1 -1.5707953071795862
    }
    DEF Cammera Pose {
      translation 0 -0.031 0.007
      children [
        Shape {
          appearance PBRAppearance {
            baseColor 0 0 0
            metalness 0
          }
          geometry Cylinder {
            height 0.004
            radius 0.01
          }
        }
      ]
    }
    DEF LIDAR Pose {
      translation 0 -0.021 0
      children [
        Shape {
          appearance PBRAppearance {
            baseColor 0 0 1
            metalness 0
          }
          geometry Cylinder {
            height 0.01
            radius 0.02
          }
        }
      ]
    }
    Solid {
      translation 0 -0.02 -0.009
      children [
        DEF front_wheel Shape {
          appearance PBRAppearance {
            baseColor 1 0 0
            roughness 1
            metalness 0
          }
          geometry Sphere {
            radius 0.011
            subdivision 4
          }
        }
      ]
      name "solid(3)"
      boundingObject USE front_wheel
      physics Physics {
      }
    }
    Solid {
      translation 0 0.03 -0.009
      children [
        DEF front_wheel Shape {
          appearance PBRAppearance {
            baseColor 0.4 1 1
            roughness 1
            metalness 0
          }
          geometry Sphere {
            radius 0.01
            subdivision 4
          }
        }
      ]
      name "solid(2)"
      boundingObject USE front_wheel
      physics Physics {
      }
    }
    DEF left_wheel HingeJoint {
      jointParameters HingeJointParameters {
        position 1412.898785598145
      }
      device [
        RotationalMotor {
          name "left wheel motor"
        }
      ]
      endPoint Solid {
        translation 0.0399999999905755 2.647830479223721e-06 2.2382123325456614e-06
        rotation 0.36950634307918456 -0.8526014118487586 0.3695076385377593 4.553593933353896
        children [
          DEF wheel Shape {
            appearance PBRAppearance {
              baseColor 1 0.3 1
              roughness 1
              metalness 0
            }
            geometry Cylinder {
              height 0.01
              radius 0.02
            }
          }
        ]
        name "solid(1)"
        boundingObject USE wheel
        physics Physics {
        }
      }
    }
    DEF right_wheel HingeJoint {
      jointParameters HingeJointParameters {
        position 1749.0885526231707
      }
      device [
        RotationalMotor {
          name "right wheel motor"
        }
      ]
      endPoint Solid {
        translation -0.03999999996270977 -2.7640835778473577e-06 -2.549857487694908e-06
        rotation 0.6791131352807664 0.2785806426468199 0.6791157302195352 2.5982105418003423
        children [
          DEF wheel_right Shape {
            appearance PBRAppearance {
              baseColor 1 0.3 1
              roughness 1
              metalness 0
            }
            geometry Cylinder {
              height 0.01
              radius 0.02
            }
          }
        ]
        boundingObject USE wheel_right
        physics Physics {
        }
      }
    }
    Pose {
      children [
        DEF Body Shape {
          appearance PBRAppearance {
            roughness 1
            metalness 0
          }
          geometry Cylinder {
            height 0.02
            radius 0.04
          }
        }
      ]
    }
  ]
  boundingObject USE Body
  physics Physics {
  }
  controller "linefollowingadvance2"
}
Group {
  children [
    Solid {
      translation -0.310001 -0.0299981 0.01
      rotation 0 0 1 1.57079
      children [
        Shape {
          appearance PBRAppearance {
            baseColor 0 0 0
            roughness 1
            metalness 0
          }
          geometry Box {
            size 0.01 0.36 0.0001
          }
        }
      ]
      name "solid(31)"
    }
    Solid {
      translation -0.129999 0.0300025 0.01
      rotation 0 0 1 -5.307179586466759e-06
      children [
        Shape {
          appearance PBRAppearance {
            baseColor 0 0 0
            roughness 1
            metalness 0
          }
          geometry Box {
            size 0.01 0.36 0.0001
          }
        }
      ]
      name "solid(32)"
    }
    Solid {
      translation -0.320001 -0.029998 0.01
      rotation 0 0 1 -5.307179586466759e-06
      children [
        Shape {
          appearance PBRAppearance {
            baseColor 0 0 0
            roughness 1
            metalness 0
          }
          geometry Box {
            size 0.01 0.68 0.0001
          }
        }
      ]
      name "solid(30)"
    }
    Solid {
      translation -0.089998 0.48 0.01
      rotation 0 0 1 1.57079
      children [
        Shape {
          appearance PBRAppearance {
            baseColor 0 0 0
            roughness 1
            metalness 0
          }
          geometry Box {
            size 0.01 0.09 0.0001
          }
        }
      ]
      name "solid(24)"
    }
    Solid {
      translation -0.179998 0.48 0.01
      rotation 0 0 1 1.57079
      children [
        Shape {
          appearance PBRAppearance {
            baseColor 0 0 0
            roughness 1
            metalness 0
          }
          geometry Box {
            size 0.01 0.09 0.0001
          }
        }
      ]
      name "solid(25)"
    }
    Solid {
      translation -0.279998 0.48 0.01
      rotation 0 0 1 1.57079
      children [
        Shape {
          appearance PBRAppearance {
            baseColor 0 0 0
            roughness 1
            metalness 0
          }
          geometry Box {
            size 0.01 0.09 0.0001
          }
        }
      ]
      name "solid(26)"
    }
    Solid {
      translation -0.259998 0.48 0.01
      rotation 0 0 1 1.57079
      children [
        Shape {
          appearance PBRAppearance {
            baseColor 0 0 0
            roughness 1
            metalness 0
          }
          geometry Box {
            size 0.01 0.09 0.0001
          }
        }
      ]
      name "solid(33)"
    }
    Solid {
      translation -0.319998 0.44 0.01
      rotation 0 0 1 3.14159
      children [
        Shape {
          appearance PBRAppearance {
            baseColor 0 0 0
            roughness 1
            metalness 0
          }
          geometry Box {
            size 0.01 0.09 0.0001
          }
        }
      ]
      name "solid(27)"
    }
    Solid {
      translation -0.319998 0.36 0.01
      rotation 0 0 1 3.14159
      children [
        Shape {
          appearance PBRAppearance {
            baseColor 0 0 0
            roughness 1
            metalness 0
          }
          geometry Box {
            size 0.01 0.09 0.0001
          }
        }
      ]
      name "solid(28)"
    }
    Solid {
      translation -0.319998 0.28 0.01
      rotation 0 0 1 3.14159
      children [
        Shape {
          appearance PBRAppearance {
            baseColor 0 0 0
            roughness 1
            metalness 0
          }
          geometry Box {
            size 0.01 0.09 0.0001
          }
        }
      ]
      name "solid(29)"
    }
    Solid {
      translation 0.08 0.2 0.01
      rotation 0 0 1 1.5708
      children [
        Shape {
          appearance PBRAppearance {
            baseColor 0 0 0
            metalness 0
          }
          geometry Box {
            size 0.01 0.09 0.0001
          }
        }
      ]
      name "solid(9)"
    }
    Solid {
      translation 0.11 0.2 0.01
      rotation 0 0 1 1.5708
      children [
        Shape {
          appearance PBRAppearance {
            baseColor 0 0 0
            roughness 1
            metalness 0
          }
          geometry Box {
            size 0.01 0.09 0.0001
          }
        }
      ]
      name "solid(10)"
    }
    Solid {
      translation 0.0400004 0.24 0.01
      rotation 0 0 1 -5.307179586466759e-06
      children [
        Shape {
          appearance PBRAppearance {
            baseColor 0 0 0
            roughness 1
            metalness 0
          }
          geometry Box {
            size 0.01 0.09 0.0001
          }
        }
      ]
      name "solid(12)"
    }
    Solid {
      translation 0.0400008 0.28 0.01
      rotation 0 0 1 -5.307179586466759e-06
      children [
        Shape {
          appearance PBRAppearance {
            baseColor 0 0 0
            roughness 1
            metalness 0
          }
          geometry Box {
            size 0.01 0.09 0.0001
          }
        }
      ]
      name "solid(13)"
    }
    Solid {
      translation 0.0400014 0.34 0.01
      rotation 0 0 1 -5.307179586466759e-06
      children [
        Shape {
          appearance PBRAppearance {
            baseColor 0 0 0
            roughness 1
            metalness 0
          }
          geometry Box {
            size 0.01 0.09 0.0001
          }
        }
      ]
      name "solid(14)"
    }
    Solid {
      translation 0.120002 0.38 0.01
      rotation 0 0 1 1.57079
      children [
        Shape {
          appearance PBRAppearance {
            baseColor 0 0 0
            metalness 0
          }
          geometry Box {
            size 0.01 0.09 0.0001
          }
        }
      ]
      name "solid(17)"
    }
    Solid {
      translation 0.350002 0.42 0.01
      rotation 0 0 1 -5.307179586466759e-06
      children [
        Shape {
          appearance PBRAppearance {
            baseColor 0 0 0
            metalness 0
          }
          geometry Box {
            size 0.01 0.09 0.0001
          }
        }
      ]
      name "solid(18)"
    }
    Solid {
      translation 0.350002 0.44 0.01
      rotation 0 0 1 -5.307179586466759e-06
      children [
        Shape {
          appearance PBRAppearance {
            baseColor 0 0 0
            roughness 1
            metalness 0
          }
          geometry Box {
            size 0.01 0.09 0.0001
          }
        }
      ]
      name "solid(19)"
    }
    Solid {
      translation 0.120002 0.48 0.01
      rotation 0 0 1 1.57079
      children [
        Shape {
          appearance PBRAppearance {
            baseColor 0 0 0
            roughness 1
            metalness 0
          }
          geometry Box {
            size 0.01 0.09 0.0001
          }
        }
      ]
      name "solid(20)"
    }
    Solid {
      translation 0.110002 0.48 0.01
      rotation 0 0 1 1.57079
      children [
        Shape {
          appearance PBRAppearance {
            baseColor 0 0 0
            roughness 1
            metalness 0
          }
          geometry Box {
            size 0.01 0.09 0.0001
          }
        }
      ]
      name "solid(21)"
    }
    Solid {
      translation 0.050002 0.48 0.01
      rotation 0 0 1 1.57079
      children [
        Shape {
          appearance PBRAppearance {
            baseColor 0 0 0
            roughness 1
            metalness 0
          }
          geometry Box {
            size 0.01 0.09 0.0001
          }
        }
      ]
      name "solid(22)"
    }
    Solid {
      translation -0.019998 0.48 0.01
      rotation 0 0 1 1.57079
      children [
        Shape {
          appearance PBRAppearance {
            baseColor 0 0 0
            roughness 1
            metalness 0
          }
          geometry Box {
            size 0.01 0.09 0.0001
          }
        }
      ]
      name "solid(23)"
    }
    Solid {
      translation 0.35 -0.26 0.01
      children [
        Shape {
          appearance PBRAppearance {
            baseColor 0 0 0
            roughness 1
            metalness 0
          }
          geometry Box {
            size 0.01 0.09 0.0001
          }
        }
      ]
    }
    Solid {
      translation 0.35 -0.19 0.01
      children [
        Shape {
          appearance PBRAppearance {
            baseColor 0 0 0
            roughness 1
            metalness 0
          }
          geometry Box {
            size 0.01 0.09 0.0001
          }
        }
      ]
      name "solid(1)"
    }
    Solid {
      translation 0.35 -0.11 0.01
      children [
        Shape {
          appearance PBRAppearance {
            baseColor 0 0 0
            roughness 1
            metalness 0
          }
          geometry Box {
            size 0.01 0.09 0.0001
          }
        }
      ]
      name "solid(2)"
    }
    Solid {
      translation 0.31 -0.07 0.01
      rotation 0 0 1 1.5708
      children [
        Shape {
          appearance PBRAppearance {
            baseColor 0 0 0
            roughness 1
            metalness 0
          }
          geometry Box {
            size 0.01 0.09 0.0001
          }
        }
      ]
      name "solid(3)"
    }
    Solid {
      translation 0.26 -0.07 0.01
      rotation 0 0 1 1.5708
      children [
        Shape {
          appearance PBRAppearance {
            baseColor 0 0 0
            roughness 1
            metalness 0
          }
          geometry Box {
            size 0.01 0.09 0.0001
          }
        }
      ]
      name "solid(4)"
    }
    Solid {
      translation 0.22 -0.03 0.01
      rotation 0 0 -1 -5.307179586466759e-06
      children [
        Shape {
          appearance PBRAppearance {
            baseColor 0 0 0
            metalness 0
          }
          geometry Box {
            size 0.01 0.09 0.0001
          }
        }
      ]
      name "solid(5)"
    }
    Solid {
      translation 0.22 0.06 0.01
      rotation 0 0 -1 -5.307179586466759e-06
      children [
        Shape {
          appearance PBRAppearance {
            baseColor 0 0 0
            roughness 1
            metalness 0
          }
          geometry Box {
            size 0.01 0.09 0.0001
          }
        }
      ]
      name "solid(6)"
    }
    Solid {
      translation 0.22 0.15 0.01
      rotation 0 0 -1 -5.307179586466759e-06
      children [
        Shape {
          appearance PBRAppearance {
            baseColor 0 0 0
            roughness 1
            metalness 0
          }
          geometry Box {
            size 0.01 0.09 0.0001
          }
        }
      ]
      name "solid(7)"
    }
    Solid {
      translation 0.18 0.2 0.01
      rotation 0 0 1 1.5708
      children [
        Shape {
          appearance PBRAppearance {
            baseColor 0 0 0
            roughness 1
            metalness 0
          }
          geometry Box {
            size 0.01 0.09 0.0001
          }
        }
      ]
      name "solid(8)"
    }
  ]
}
